<?xml version="1.0" ?>
<!-- =================================================================================== -->
<!-- |    This document was autogenerated by xacro from panda_arm.urdf.xacro           | -->
<!-- |    EDITING THIS FILE BY HAND IS NOT RECOMMENDED                                 | -->
<!-- =================================================================================== -->
<mujoco>
  <compiler angle="radian" />
  <option collision ="predefined" cone="elliptic" jacobian="sparse" tolerance="1e-6" iterations="30" solver="CG" timestep="0.002" noslip_iterations="30" noslip_tolerance="1e-5"/>
  <size njmax="8000" nconmax="4000" />
  <asset>
    <mesh name="panda_link0"  file="../meshes/visual/link0.stl" />
    <mesh name="panda_link1"  file="../meshes/visual/link1.stl" />
    <mesh name="panda_link2"  file="../meshes/visual/link2.stl" />
    <mesh name="panda_link3"  file="../meshes/visual/link3.stl" />
    <mesh name="panda_link4"  file="../meshes/visual/link4.stl" />
    <mesh name="panda_link5"  file="../meshes/visual/link5.stl" />
    <mesh name="panda_link6"  file="../meshes/visual/link6.stl" />
    <mesh name="panda_link7"  file="../meshes/visual/link7.stl" />
    <mesh name="panda_hand"   file="../meshes/visual/hand.stl" />
    <mesh name="panda_finger" file="../meshes/visual/finger.stl" />
  </asset>

  <asset>
    <texture type="skybox" builtin="gradient" width="128" height="128" rgb1=".4 .6 .8" rgb2="0 0 0"/> 
    <texture name="texgeom" type="cube" builtin="flat" mark="cross" width="128" height="128" 
        rgb1="0.6 0.6 0.6" rgb2="0.6 0.6 0.6" markrgb="1 1 1"/>  
    <texture name="texplane" type="2d" builtin="checker" rgb1=".2 .3 .4" rgb2=".1 0.15 0.2"
        width="512" height="512"/>  
    <material name='MatPlane' reflectance='0.3' texture="texplane" texrepeat="1 1" texuniform="true"/>
  </asset>

  <visual>
    <quality shadowsize="2048" offsamples="16"/>
    <map znear="0.1" force="0.05"/>
  </visual>

  <worldbody>
    <light directional="true" diffuse=".8 .8 .8" pos="0 0 10" dir="0 0 -10"/>
    <geom name="ground" pos="0 0 0" type="plane" size="10 10 .05" rgba=".7 .7 .7 1" material="MatPlane"/>

    <body name="panda_link0" pos="0 0 0" quat="1 0 0 0">
      <inertial pos="-0.041018 -0.00014 0.049974" quat="1 0 0 0" mass="0.629769" fullinertia="0.00315 0.00388 0.004285 8.2904E-07 0.00015 8.2299E-06" />
      <geom type="mesh" rgba=".95 .99 .92 1" mesh="panda_link0" />
      <body name="panda_link1" pos="0 0 0.333" quat="1 0 0 0">
        <joint name="panda_joint1" pos="0 0 0" axis="0 0 1" limited="true" range="-2.8973 2.8973" damping="10" frictionloss="1" />
        <inertial pos="0.003875 0.002081 -0.04762" quat="1 0 0 0" mass="4.970684" fullinertia="0.70337 0.70661 0.0091170 -0.00013900 0.0067720 0.019169" />
        <geom type="mesh" rgba=".95 .99 .92 1" mesh="panda_link1" />
        <body name="panda_link2" pos="0 0 0" euler="-1.5707963267948966 0 0">
          <joint name="panda_joint2" pos="0 0 0" axis="0 0 1" limited="true" range="-1.7628 1.7628" damping="10" frictionloss="1" />
          <inertial pos="-0.003141 -0.02872  0.003495" quat="1 0 0 0" mass="0.646926" fullinertia="0.0079620 2.8110e-02 2.5995e-02 -3.9250e-3 1.0254e-02 7.0400e-04" />
          <geom type="mesh" rgba=".95 .99 .92 1" mesh="panda_link2" />
          <body name="panda_link3" pos="0 -0.316 0" euler="1.5707963267948966 0 0">
            <joint name="panda_joint3" pos="0 0 0" axis="0 0 1" limited="true" range="-2.8973 2.8973" damping="10" frictionloss="1" />
            <inertial pos="2.7518e-02 3.9252e-02 -6.6502e-02" quat="1 0 0 0" mass="3.228604" fullinertia="3.7242e-02 3.6155e-02 1.0830e-02 -4.7610e-03 -1.1396e-02 -1.2805e-02" />
            <geom type="mesh" rgba=".95 .99 .92 1" mesh="panda_link3" />
            <body name="panda_link4" pos="0.0825 0 0" euler="1.5707963267948966 0 0">
              <joint name="panda_joint4" pos="0 0 0" axis="0 0 1" limited="true" range="-3.0718 -0.0698" damping="10" frictionloss="1" />
              <inertial pos="-5.317e-02 1.04419e-01 2.7454e-02" quat="1 0 0 0" mass="3.587895" fullinertia="2.5853e-02 1.9552e-02 2.8323e-02 7.7960e-03 -1.3320e-03 8.6410e-03" />
              <geom type="mesh" rgba=".95 .99 .92 1" mesh="panda_link4" />
              <body name="panda_link5" pos="-0.0825 0.384 0" euler="-1.5707963267948966 0 0">
                <joint name="panda_joint5" pos="0 0 0" axis="0 0 1" limited="true" range="-2.8973 2.8973" damping="10" frictionloss="1" />
                <inertial pos="-1.1953e-02 4.1065e-02 -3.8437e-02" quat="1 0 0 0" mass="1.225946" fullinertia="3.5549e-02 2.9474e-02 8.6270e-03 -2.1170e-03 -4.0370e-03 2.2900e-04" />
                <geom type="mesh" rgba=".95 .99 .92 1" mesh="panda_link5" />
                <body name="panda_link6" pos="0 0 0" euler="1.5707963267948966 0 0">
                  <joint name="panda_joint6" pos="0 0 0" axis="0 0 1" limited="true" range="-0.0175 3.7525" damping="10" frictionloss="1" />
                  <inertial pos="6.0149e-02 -1.4117e-02 -1.0517e-02" quat="1 0 0 0" mass="1.666555" fullinertia="1.9640e-03 4.3540e-03 5.4330e-03 1.0900e-04 -1.1580e-03 3.4100e-04" />
                  <geom type="mesh" rgba=".95 .99 .92 1" mesh="panda_link6" />
                  <body name="panda_link7" pos="0.088 0 0" euler="1.5707963267948966 0 0">
                    <joint name="panda_joint7" pos="0 0 0" axis="0 0 1" limited="true" range="-2.8973 2.8973" damping="10" frictionloss="1" />
                    <inertial pos="1.0517e-02 -4.252e-03 6.1597e-02" quat="1 0 0 0" mass="7.35522e-01" fullinertia="1.2516e-02 1.0027e-02 4.8150e-03 -4.2800e-04 -1.1960e-03 -7.4100e-04" />
                    <geom type="mesh" rgba=".95 .99 .92 1" mesh="panda_link7" />
                    <!-- <geom type="cylinder" pos="0.0424 0.0424 -0.0250" euler="3.141592653589793 1.5707963267948966 1.5707963267948966" size="0.06 0.01" contype="1" conaffinity="1" condim="3" />
                      <geom type="sphere" pos="0.0424 0.0424 -0.02" euler="0 0 0" size="0.06" contype="1" conaffinity="1" condim="3" />
                      <geom type="sphere" pos="0.0424 0.0424 -0.03" euler="0 0 0" size="0.06" contype="1" conaffinity="1" condim="3" /> -->
                    <body name="panda_link8" pos="0 0 0.107" euler="0 0 0">
                      <!-- <geom type="cylinder" pos="0 0 0.04" euler="0 1.5707963267948966 1.5707963267948966" size="0.07 0.01" contype="1" conaffinity="1" condim="3" />
                      <geom type="sphere" pos="0 -0.05 0.04" euler="0 0 0" size="0.07" contype="1" conaffinity="1" condim="3" />
                      <geom type="sphere" pos="0 0.05 0.04" euler="0 0 0" size="0.07" contype="1" conaffinity="1" condim="3" />
                      <geom type="cylinder" pos="0 0 0.1" euler="0 1.5707963267948966 1.5707963267948966" size="0.05 0.01" contype="1" conaffinity="1" condim="3" />
                      <geom type="sphere" pos="0 -0.05 0.1" euler="0 0 0" size="0.05" contype="1" conaffinity="1" condim="3" />
                      <geom type="sphere" pos="0 0.05 0.1" euler="0 0 0" size="0.05" contype="1" conaffinity="1" condim="3" /> -->
                      <body name="panda_hand" pos="0 0 0" euler="0 0 -0.7853981633974483">
                        <inertial pos="-0.01 0 0.03" quat="1 0 0 0" mass="0.73" diaginertia="0.001 0.0025 0.0017" />
                        <geom type="mesh" rgba=".95 .99 .92 1" mesh="panda_hand" />
                        <body name="panda_tcp" pos="0 0 0.1034" euler="0 0 0" />
                        <body name="panda_leftfinger" pos="0 0 0.0584" euler="0 0 0" >
                          <inertial pos="0 0 0" quat="1 0 0 0" mass="0.015" diaginertia="2.375e-06 2.375e-06 7.5e-07" />
                          <joint name="panda_leftfinger_joint" pos="0 0 0" axis="0 1 0" type="slide" limited="true" range="0.0 0.04" damping="10" frictionloss="1" />
                          <geom type="mesh" rgba=".5 .6 .7 .4" mesh="panda_finger" />
                        </body>
                        <body name="panda_rightfinger" pos="0 0 0.0584" euler="0 0 3.141592653589793">
                          <inertial pos="0 0 0" quat="1 0 0 0" mass="0.015" diaginertia="2.375e-06 2.375e-06 7.5e-07" />
                          <joint name="panda_rightfinger_joint" pos="0 0 0" axis="0 -1 0" type="slide" limited="true" range="0.0 0.04" damping="10" frictionloss="1" />
                          <geom type="mesh" rgba=".5 .6 .7 .4" mesh="panda_finger" />
                        </body>
                      </body>
                    </body>
                  </body>
                </body>
              </body>
            </body>
          </body>
        </body>
      </body>
    </body>
  </worldbody>
</mujoco>